Workbook

Sheet Summary
A1: 도그스하이 (DOGS HIGH) — 투자자 요약 (Summary)
A2: 작성 2026-08-03 · 원본 모델: dogshigh-growth-model.xlsx · 이 시트의 모든 값은 아래 시트(Assumptions/UnitEcon/Projection)에서 실시간 계산됩니다.
A4: ⚠️ 가정 주의 (DISCLAIMER) — 반드시 읽어주세요
A5: 1. 도그스하이는 프리런칭입니다. 2026-08-03 기준 유료 고객 0명, 누적 매출 0원. 이 파일에 실적(actual) 수치는 한 줄도 없습니다.
A6: 2. 이 워크북의 모든 숫자는 가설(hypothesis)과 시장 앵커 기반 추정입니다 — 가격 ₩9,900+3,000/km(앱 정책), 멤버십 ₩199–299k(플레이북 가설), 테이크 20%(와요·비포펫형 15–30% 대역), PG 3.3%(통상 단가, 견적 전), 보험 ₩1,000/런(견적 미수령).
A7: 3. 리텐션·전환율·CAC·리퍼럴 계수는 전부 미검증 가설입니다. 첫 실데이터는 2026년 12월 Phase 3 게이트에서 확보됩니다.
A8: 4. 계절성(폭염·한파), 환불/분쟁, 세금, 창업자 인건비는 이 모델에 포함되어 있지 않습니다. 창업자 생활비·개발·법률 비용은 별도 자금사용계획(financial-slides.md 슬라이드 B) 참조.
A9: 5. 노란색 셀 = 핵심 레버(테이크레이트·리텐션). 이 두 값을 바꾸면 결론이 바뀝니다 — 그것이 이 모델의 요점입니다.
A11: 1. 기본 케이스 핵심 지표 (모델 기본값: 테이크 20% × 월 리텐션 70%)
A12: 지표 | B12: 값 | C12: 단위 | D12: 출처 / 라벨
A13: 런 1회 GMV | B13: =UnitEcon!B4 -> 24900 | C13: ₩ | D13: 앱 가격정책 9,900 + 3,000/km × 5km [가설: 평균거리]
A14: 런 1회 순기여 | B14: =UnitEcon!B8 -> 3158.3 | C14: ₩ | D14: 테이크 − PG − 보험
A15: 멤버십 가격 | B15: =Assumptions!B8 -> 249000 | C15: ₩/월 | D15: [가설] 199–299k 대역 중간값, 주 2–3회
A16: 도그-월 순기여 | B16: =UnitEcon!B12 -> 31583 | C16: ₩/월 | D16: 이 사업의 실질 단위 매출
A17: 기대 수명 | B17: =UnitEcon!B13 -> 3.3333333 | C17: 개월 | D17: 수식: 1 ÷ (1 − 월 리텐션) [가설: 기하분포]
A18: LTV | B18: =UnitEcon!B14 -> 105276.67 | C18: ₩ | D18: 도그-월 순기여 × 기대 수명
A19: 최저 CAC 채널 LTV:CAC (한강 이벤트) | B19: =UnitEcon!C26 -> 7.0184444 | C19: 배 | D19: [추정] 3.0x 미만은 스케일 금지
A20: 12개월 GMV (단일 동) | B20: =SUM(Projection!B9:M9) -> 69379286 | C20: ₩ | D20: 모델 Projection 시트
A21: 12개월 순플랫폼 수익 | B21: =SUM(Projection!B14:M14) -> 8800024.1 | C21: ₩ | D21: 테이크 − PG − 보험 합계
A22: 12개월 총비용 | B22: =SUM(Projection!B20:M20) -> 29097067 | C22: ₩ | D22: 이벤트·무료런·마케팅·고정운영 (창업자 인건비 제외)
A23: 12개월 누적 순현금 | B23: =Projection!M22 -> -20297043 | C23: ₩ | D23: ⚠️ 음수 — 첫 동은 이익 유닛이 아님
A24: 12개월차 유료견 | B24: =Projection!M7 -> 26.539785 | C24: 마리 | D24: 성장 플래토
A25: 12개월차 필요 인증 러너 | B25: =Projection!M25 -> 12 | C25: 명 | D25: 1.5배 오버서플라이 기준
A27: 2. 3-시나리오 비교 — 리텐션 60/70/80% × 테이크 20/25/25%
A28: 노란 셀(리텐션·테이크)만 바꾸면 아래 전 항목이 재계산됩니다. 이 두 레버가 전부입니다.
A29: 항목 | B29: 보수 (Conservative) | C29: 기본 (Base) | D29: 낙관 (Optimistic) | E29: 참고: 모델 하드코딩 기본값
A30: 월 리텐션 ← 레버 | B30: 0.6 | C30: 0.7 | D30: 0.8 | E30: =Assumptions!B20 -> 0.7
A31: 플랫폼 테이크레이트 ← 레버 | B31: 0.2 | C31: 0.25 | D31: 0.25 | E31: =Assumptions!B13 -> 0.2
A32: 도그-월 순기여 (₩) | B32: =Assumptions!$B$8*B31-Assumptions!$B$8*Assumptions!$B$14-Assumptions!$B$9*Assumptions!$B$15 -> 31583 | C32: =Assumptions!$B$8*C31-Assumptions!$B$8*Assumptions!$B$14-Assumptions!$B$9*Assumptions!$B$15 -> 44033 | D32: =Assumptions!$B$8*D31-Assumptions!$B$8*Assumptions!$B$14-Assumptions!$B$9*Assumptions!$B$15 -> 44033 | E32: =Assumptions!$B$8*E31-Assumptions!$B$8*Assumptions!$B$14-Assumptions!$B$9*Assumptions!$B$15 -> 31583 | F32: 멤버십가×테이크 − PG − 보험(월 런수×건당)
A33: 기대 수명 (개월) | B33: =1/(1-B30) -> 2.5 | C33: =1/(1-C30) -> 3.3333333 | D33: =1/(1-D30) -> 5 | E33: =1/(1-E30) -> 3.3333333 | F33: 수식: 1 ÷ (1 − 월 리텐션)
A34: LTV (₩) | B34: =B32*B33 -> 78957.5 | C34: =C32*C33 -> 146776.67 | D34: =D32*D33 -> 220165 | E34: =E32*E33 -> 105276.67 | F34: 도그-월 순기여 × 기대 수명
A35: LTV : CAC — 한강 이벤트 | B35: =B34/Assumptions!$B$38 -> 5.2638333 | C35: =C34/Assumptions!$B$38 -> 9.7851111 | D35: =D34/Assumptions!$B$38 -> 14.677667 | E35: =E34/Assumptions!$B$38 -> 7.0184444 | F35: CAC ₩15,000 [추정]
A36: LTV : CAC — 멍스타그램 시딩 | B36: =B34/Assumptions!$B$39 -> 2.6319167 | C36: =C34/Assumptions!$B$39 -> 4.8925556 | D36: =D34/Assumptions!$B$39 -> 7.3388333 | E36: =E34/Assumptions!$B$39 -> 3.5092222 | F36: CAC ₩30,000 [추정]
A37: 러너 지급 / 런 (₩) | B37: =Assumptions!$B$7*(1-B31) -> 19920 | C37: =Assumptions!$B$7*(1-C31) -> 18675 | D37: =Assumptions!$B$7*(1-D31) -> 18675 | E37: =Assumptions!$B$7*(1-E31) -> 19920 | F37: 테이크 인상은 러너 지급을 깎습니다 — 채용 카피 인쇄 전 결정
A38: LTV : CAC — 리퍼럴 (무료런 2회) | B38: =B34/(2*B37) -> 1.981865 | C38: =C34/(2*C37) -> 3.9297635 | D38: =D34/(2*D37) -> 5.8946452 | E38: =E34/(2*E37) -> 2.6424866 | F38: 보상을 1회로 낮추면 배수가 2배
A39: LTV : CAC — 페이드 인스타그램 | B39: =B34/Assumptions!$B$41 -> 1.3159583 | C39: =C34/Assumptions!$B$41 -> 2.4462778 | D39: =D34/Assumptions!$B$41 -> 3.6694167 | E39: =E34/Assumptions!$B$41 -> 1.7546111 | F39: CAC ₩60,000 [가설] — 3.0x 미만이면 집행 금지
A40: 안정상태 유료견 (마리) | B40: =Assumptions!$B$25/(1-B30-Assumptions!$B$24) -> 18.75 | C40: =Assumptions!$B$25/(1-C30-Assumptions!$B$24) -> 27.272727 | D40: =Assumptions!$B$25/(1-D30-Assumptions!$B$24) -> 50 | E40: =Assumptions!$B$25/(1-E30-Assumptions!$B$24) -> 27.272727 | F40: 수식: 월 오가닉·이벤트 신규 ÷ (1 − 리텐션 − 리퍼럴계수). 리텐션 10%p가 밀도를 배로 만듭니다
A41: 안정상태 월 순플랫폼 수익 (₩) | B41: =B40*B32 -> 592181.25 | C41: =C40*C32 -> 1200900 | D41: =D40*D32 -> 2201650 | E41: =E40*E32 -> 861354.55
A42: 안정상태 월 비용 (₩) | B42: =Assumptions!$B$28*Assumptions!$B$29+Assumptions!$B$30+Assumptions!$B$24*B40*2*B37 -> 2159760 | C42: =Assumptions!$B$28*Assumptions!$B$29+Assumptions!$B$30+Assumptions!$B$24*C40*2*C37 -> 2181490.9 | D42: =Assumptions!$B$28*Assumptions!$B$29+Assumptions!$B$30+Assumptions!$B$24*D40*2*D37 -> 2249400 | E42: =Assumptions!$B$28*Assumptions!$B$29+Assumptions!$B$30+Assumptions!$B$24*E40*2*E37 -> 2186923.6 | F42: 이벤트 + 고정운영 + 리퍼럴 무료런 보조 (창업자 인건비 제외)
A43: 안정상태 월 순현금 (₩) | B43: =B41-B42 -> -1567578.8 | C43: =C41-C42 -> -980590.91 | D43: =D41-D42 -> -47750 | E43: =E41-E42 -> -1325569.1 | F43: ⚠️ 기본 가정에서 첫 동은 월 흑자가 아닙니다
...

Sheet ReadMe
A1: DOGS HIGH — Single-동 Growth Model
A2: Built 2026-07-30. Companion to docs/marketing-fundraising.md §3 (90-day playbook) and docs/positioning.md.
A4: HOW TO USE
A5: Blue text = hardcoded input you can edit. Yellow fill = the key levers. Black = formula, do not overwrite. Green = pulls from another sheet.
A6: All ₩ amounts are KRW. All rates are stored as fractions (0.20 = 20%).
A7: Every number here is a hypothesis from docs/ (pricing 9,900 + 3,000/km; membership ₩199–299k guess; 비포펫/와요 anchors). Replace with real data as it arrives.
A9: WHAT THE BASE CASE ALREADY SHOWS (spoilers)
A10: 1. At 20% take, net contribution is only ~₩31.6k per dog-month after PG fees + insurance — LTV at 70% retention ≈ ₩105k. The business is take-rate- and retention-sensitive, not volume-sensitive. Try 25% take x 80% retention on the UnitEcon sensitivity grid.
A11: 2. The Phase-3 fundraising target (≥50 paying dogs by ~month 3) does NOT fall out of a 40-dog founding cohort at 40% conversion — it needs a bigger cohort (~80+ dogs) or >60% conversion. Edit Assumptions B21/B23 and watch Projection row 7.
A12: 3. With events at 4x/mo the single 동 plateaus (~27-30 active dogs on base referral/organic rates) below monthly cost coverage — the first 동 is a proof-of-density unit, not a profit unit. That is a fine story IF stated on purpose in the deck.
A13: 4. Referral's true cost (2 x runner payout ≈ ₩39.8k) lands at ~2.6x LTV:CAC — BELOW the 3x bar at base case. It works only if referred dogs retain better than average (they usually do) or if the reward drops to 1 free run. Cleanest channels at base case: events (~7x) and 멍스타그램 seeding (~3.5x).
A15: SHEETS
A16: Assumptions — every input in one place. UnitEcon — per-run and per-dog-month economics, LTV sensitivity (take x retention), CAC by channel. Projection — 12-month single-동 monthly model. Supply — runners needed per demand level.

Sheet Assumptions
A1: Assumptions — edit blue cells; yellow = key levers
A3: PRICING & PRODUCT
A4: Base fare per run (₩) | B4: 9900 | C4: From app pricing: 9,900 + km x 3,000 (hi-club approval pricing)
A5: Per-km rate (₩/km) | B5: 3000
A6: Avg run distance (km) | B6: 5 | C6: Hypothesis — replace with real avg from runs table
A7: Avg GMV per run (₩) | B7: =B4+B5*B6 -> 24900
A8: Membership price (₩/mo) | B8: 249000 | C8: Playbook hypothesis ₩199–299k for 주 2–3회 — midpoint
A9: Runs per member dog / month | B9: 10 | C9: 주 2–3회 ≈ 10/mo
A10: Effective per-run price on membership (₩) | B10: =B8/B9 -> 24900 | C10: Sanity check vs B7 — membership should be ≈ or slightly below single-run price
A12: MARKETPLACE ECONOMICS
A13: Platform take rate | B13: 0.2 | C13: Hypothesis. 와요/비포펫-type marketplaces run 15–30%
A14: PG fee (% of GMV) | B14: 0.033 | C14: Typical KR PG (카드) ~3.3% incl VAT — verify with PG quote
A15: Insurance cost per run (₩) | B15: 1000 | C15: Hypothesis — no quote yet; bundled per-booking cover is a marketing asset (only 12.8% of owners insured, KB 2025)
A16: Runner payout share | B16: =1-B13 -> 0.8
A17: Runner payout per avg run (₩) | B17: =B7*B16 -> 19920 | C17: Recruiting math: ~40min run + handover ≈ 1h → compare vs 2026 min wage ₩10,320/h
A19: DEMAND & RETENTION
A20: Monthly member retention (base) | B20: 0.7 | C20: THE number. 60/70/80% scenarios on UnitEcon grid
A21: Founding cohort (free-run dogs) | B21: 40 | C21: Playbook says 30–50; 50-dog Phase-3 target wants ~80+ here (see ReadMe)
A22: Free runs per founding dog | B22: 2
A23: Founding → paid conversion | B23: 0.4 | C23: Hypothesis — free-trial-to-paid for high-touch local services 30–50%
A24: Referral: new dogs per active dog / mo | B24: 0.08 | C24: Hypothesis — 1 referred dog per ~12 active dogs per month
A25: Organic + event new dogs / mo | B25: 6 | C25: Saturday event conversions + 당근/카페/플레이스 inbound, from month 2
A27: COSTS
A28: Event cost per event (₩) | B28: 400000 | C28: Playbook ₩300–500k: bibs, banner, water, treats — halves with a snack sponsor
A29: Events per month | B29: 4
A30: Fixed opex / mo (₩) | B30: 500000 | C30: Tools, print/QR, misc — pre-salary scrappy mode
A32: RUNNER SUPPLY
A33: Runner capacity (runs / week) | B33: 8 | C33: Part-time student/crew runner ~2 runs x 4 days
A34: Oversupply factor | B34: 1.5 | C34: Owners must never see an empty map
A35: Weeks per month | B35: 4.33
A37: CAC HYPOTHESES (₩ per acquired PAYING dog)
A38: Han River event | B38: 15000 | C38: Event cost ÷ expected conversions — refine with real data
A39: 멍스타그램 seeding | B39: 30000 | C39: Gifted runs ÷ attributed signups
A40: Referral (2 free runs, both sides) | B40: =2*B17 -> 39840 | C40: Real cost = 2 x runner payout
A41: Paid Instagram | B41: 60000 | C41: Hypothesis — do not scale until organic CAC known (playbook rule)

Sheet UnitEcon
A1: Unit economics
A3: PER RUN
A4: GMV per run | B4: =Assumptions!B7 -> 24900
A5: Platform take | B5: =B4*Assumptions!B13 -> 4980
A6: PG fee | B6: =B4*Assumptions!B14 -> 821.7
A7: Insurance | B7: =Assumptions!B15 -> 1000
A8: Net contribution per run | B8: =B5-B6-B7 -> 3158.3
A10: PER DOG-MONTH (membership)
A11: GMV per dog-month | B11: =Assumptions!B8 -> 249000
A12: Net contribution per dog-month | B12: =B11*Assumptions!B13-B11*Assumptions!B14-Assumptions!B9*Assumptions!B15 -> 31583
A13: Expected lifetime (months) | B13: =1/(1-Assumptions!B20) -> 3.3333333
A14: LTV (₩) | B14: =B12*B13 -> 105276.67
A16: LTV SENSITIVITY — take rate (rows) x monthly retention (cols)
A17: take ↓ / retention → | B17: 0.6 | C17: 0.7 | D17: 0.8 | E17: 0.85
A18: 0.15 | B18: =(Assumptions!$B$8*$A18-Assumptions!$B$8*Assumptions!$B$14-Assumptions!$B$9*Assumptions!$B$15)/(1-B$17) -> 47832.5 | C18: =(Assumptions!$B$8*$A18-Assumptions!$B$8*Assumptions!$B$14-Assumptions!$B$9*Assumptions!$B$15)/(1-C$17) -> 63776.667 | D18: =(Assumptions!$B$8*$A18-Assumptions!$B$8*Assumptions!$B$14-Assumptions!$B$9*Assumptions!$B$15)/(1-D$17) -> 95665 | E18: =(Assumptions!$B$8*$A18-Assumptions!$B$8*Assumptions!$B$14-Assumptions!$B$9*Assumptions!$B$15)/(1-E$17) -> 127553.33
A19: 0.2 | B19: =(Assumptions!$B$8*$A19-Assumptions!$B$8*Assumptions!$B$14-Assumptions!$B$9*Assumptions!$B$15)/(1-B$17) -> 78957.5 | C19: =(Assumptions!$B$8*$A19-Assumptions!$B$8*Assumptions!$B$14-Assumptions!$B$9*Assumptions!$B$15)/(1-C$17) -> 105276.67 | D19: =(Assumptions!$B$8*$A19-Assumptions!$B$8*Assumptions!$B$14-Assumptions!$B$9*Assumptions!$B$15)/(1-D$17) -> 157915 | E19: =(Assumptions!$B$8*$A19-Assumptions!$B$8*Assumptions!$B$14-Assumptions!$B$9*Assumptions!$B$15)/(1-E$17) -> 210553.33
A20: 0.25 | B20: =(Assumptions!$B$8*$A20-Assumptions!$B$8*Assumptions!$B$14-Assumptions!$B$9*Assumptions!$B$15)/(1-B$17) -> 110082.5 | C20: =(Assumptions!$B$8*$A20-Assumptions!$B$8*Assumptions!$B$14-Assumptions!$B$9*Assumptions!$B$15)/(1-C$17) -> 146776.67 | D20: =(Assumptions!$B$8*$A20-Assumptions!$B$8*Assumptions!$B$14-Assumptions!$B$9*Assumptions!$B$15)/(1-D$17) -> 220165 | E20: =(Assumptions!$B$8*$A20-Assumptions!$B$8*Assumptions!$B$14-Assumptions!$B$9*Assumptions!$B$15)/(1-E$17) -> 293553.33
A21: 0.3 | B21: =(Assumptions!$B$8*$A21-Assumptions!$B$8*Assumptions!$B$14-Assumptions!$B$9*Assumptions!$B$15)/(1-B$17) -> 141207.5 | C21: =(Assumptions!$B$8*$A21-Assumptions!$B$8*Assumptions!$B$14-Assumptions!$B$9*Assumptions!$B$15)/(1-C$17) -> 188276.67 | D21: =(Assumptions!$B$8*$A21-Assumptions!$B$8*Assumptions!$B$14-Assumptions!$B$9*Assumptions!$B$15)/(1-D$17) -> 282415 | E21: =(Assumptions!$B$8*$A21-Assumptions!$B$8*Assumptions!$B$14-Assumptions!$B$9*Assumptions!$B$15)/(1-E$17) -> 376553.33
A24: CAC BY CHANNEL vs LTV (base case)
A25: Channel | B25: CAC | C25: LTV : CAC
A26: Han River event | B26: =Assumptions!B38 -> 15000 | C26: =IF(B26=0,"-",$B$14/B26) -> 7.0184444
A27: 멍스타그램 seeding | B27: =Assumptions!B39 -> 30000 | C27: =IF(B27=0,"-",$B$14/B27) -> 3.5092222
A28: Referral | B28: =Assumptions!B40 -> 39840 | C28: =IF(B28=0,"-",$B$14/B28) -> 2.6424866
A29: Paid Instagram | B29: =Assumptions!B41 -> 60000 | C29: =IF(B29=0,"-",$B$14/B29) -> 1.7546111
A31: Rule of thumb: scale nothing below 3.0x. Base case: event 7.0x and seeding 3.5x clear it; referral 2.6x needs better-retaining referees or a 1-run reward; paid IG 1.75x — do not scale.

Sheet Projection
A1: Month | B1: 1 | C1: 2 | D1: 3 | E1: 4 | F1: 5 | G1: 6 | H1: 7 | I1: 8 | J1: 9 | K1: 10 | L1: 11 | M1: 12
A3: New — founding conversion | B3: =Assumptions!B21*Assumptions!B23 -> 16 | C3: 0 | D3: 0 | E3: 0 | F3: 0 | G3: 0 | H3: 0 | I3: 0 | J3: 0 | K3: 0 | L3: 0 | M3: 0
A4: New — organic + event | B4: 0 | C4: =Assumptions!$B$25 -> 6 | D4: =Assumptions!$B$25 -> 6 | E4: =Assumptions!$B$25 -> 6 | F4: =Assumptions!$B$25 -> 6 | G4: =Assumptions!$B$25 -> 6 | H4: =Assumptions!$B$25 -> 6 | I4: =Assumptions!$B$25 -> 6 | J4: =Assumptions!$B$25 -> 6 | ... M4: =Assumptions!$B$25 -> 6
A5: New — referral | B5: 0 | C5: =Assumptions!$B$24*B7 -> 1.28 | D5: =Assumptions!$B$24*C7 -> 1.4784 | E5: =Assumptions!$B$24*D7 -> 1.633152 | F5: =Assumptions!$B$24*E7 -> 1.7538586 | G5: =Assumptions!$B$24*F7 -> 1.8480097 | H5: =Assumptions!$B$24*G7 -> 1.9214475 | I5: =Assumptions!$B$24*H7 -> 1.9787291 | J5: =Assumptions!$B$24*I7 -> 2.0234087 | ... M5: =Assumptions!$B$24*L7 -> 2.1066446
A6: Total new paying dogs | B6: =SUM(B3:B5) -> 16 | C6: =SUM(C3:C5) -> 7.28 | D6: =SUM(D3:D5) -> 7.4784 | E6: =SUM(E3:E5) -> 7.633152 | F6: =SUM(F3:F5) -> 7.7538586 | G6: =SUM(G3:G5) -> 7.8480097 | H6: =SUM(H3:H5) -> 7.9214475 | I6: =SUM(I3:I5) -> 7.9787291 | ... M6: =SUM(M3:M5) -> 8.1066446
A7: Active paying dogs | B7: =B6 -> 16 | C7: =B7*Assumptions!$B$20+C6 -> 18.48 | D7: =C7*Assumptions!$B$20+D6 -> 20.4144 | E7: =D7*Assumptions!$B$20+E6 -> 21.923232 | F7: =E7*Assumptions!$B$20+F6 -> 23.100121 | G7: =F7*Assumptions!$B$20+G6 -> 24.018094 | H7: =G7*Assumptions!$B$20+H6 -> 24.734114 | I7: =H7*Assumptions!$B$20+I6 -> 25.292609 | J7: =I7*Assumptions!$B$20+J6 -> 25.728235 | ... M7: =L7*Assumptions!$B$20+M6 -> 26.539785
A8: Runs delivered | B8: =B7*Assumptions!$B$9 -> 160 | C8: =C7*Assumptions!$B$9 -> 184.8 | D8: =D7*Assumptions!$B$9 -> 204.144 | E8: =E7*Assumptions!$B$9 -> 219.23232 | F8: =F7*Assumptions!$B$9 -> 231.00121 | G8: =G7*Assumptions!$B$9 -> 240.18094 | H8: =H7*Assumptions!$B$9 -> 247.34114 | I8: =I7*Assumptions!$B$9 -> 252.92609 | ... M8: =M7*Assumptions!$B$9 -> 265.39785
A9: GMV (₩) | B9: =B7*Assumptions!$B$8 -> 3984000 | C9: =C7*Assumptions!$B$8 -> 4601520 | D9: =D7*Assumptions!$B$8 -> 5083185.6 | E9: =E7*Assumptions!$B$8 -> 5458884.8 | F9: =F7*Assumptions!$B$8 -> 5751930.1 | G9: =G7*Assumptions!$B$8 -> 5980505.5 | H9: =H7*Assumptions!$B$8 -> 6158794.3 | I9: =I7*Assumptions!$B$8 -> 6297859.5 | ... M9: =M7*Assumptions!$B$8 -> 6608406.5
A11: Platform take | B11: =B9*Assumptions!$B$13 -> 796800 | C11: =C9*Assumptions!$B$13 -> 920304 | D11: =D9*Assumptions!$B$13 -> 1016637.1 | E11: =E9*Assumptions!$B$13 -> 1091777 | F11: =F9*Assumptions!$B$13 -> 1150386 | G11: =G9*Assumptions!$B$13 -> 1196101.1 | H11: =H9*Assumptions!$B$13 -> 1231758.9 | I11: =I9*Assumptions!$B$13 -> 1259571.9 | ... M11: =M9*Assumptions!$B$13 -> 1321681.3
A12: PG fees | B12: =B9*Assumptions!$B$14 -> 131472 | C12: =C9*Assumptions!$B$14 -> 151850.16 | D12: =D9*Assumptions!$B$14 -> 167745.12 | E12: =E9*Assumptions!$B$14 -> 180143.2 | F12: =F9*Assumptions!$B$14 -> 189813.69 | G12: =G9*Assumptions!$B$14 -> 197356.68 | H12: =H9*Assumptions!$B$14 -> 203240.21 | I12: =I9*Assumptions!$B$14 -> 207829.36 | ... M12: =M9*Assumptions!$B$14 -> 218077.42
A13: Insurance | B13: =B8*Assumptions!$B$15 -> 160000 | C13: =C8*Assumptions!$B$15 -> 184800 | D13: =D8*Assumptions!$B$15 -> 204144 | E13: =E8*Assumptions!$B$15 -> 219232.32 | F13: =F8*Assumptions!$B$15 -> 231001.21 | G13: =G8*Assumptions!$B$15 -> 240180.94 | H13: =H8*Assumptions!$B$15 -> 247341.14 | I13: =I8*Assumptions!$B$15 -> 252926.09 | ... M13: =M8*Assumptions!$B$15 -> 265397.85
A14: Net platform revenue | B14: =B11-B12-B13 -> 505328 | C14: =C11-C12-C13 -> 583653.84 | D14: =D11-D12-D13 -> 644748 | E14: =E11-E12-E13 -> 692401.44 | F14: =F11-F12-F13 -> 729571.12 | G14: =G11-G12-G13 -> 758563.47 | H14: =H11-H12-H13 -> 781177.51 | I14: =I11-I12-I13 -> 798816.46 | ... M14: =M11-M12-M13 -> 838206.04
A16: Events | B16: =Assumptions!$B$28*Assumptions!$B$29 -> 1600000 | C16: =Assumptions!$B$28*Assumptions!$B$29 -> 1600000 | D16: =Assumptions!$B$28*Assumptions!$B$29 -> 1600000 | E16: =Assumptions!$B$28*Assumptions!$B$29 -> 1600000 | F16: =Assumptions!$B$28*Assumptions!$B$29 -> 1600000 | G16: =Assumptions!$B$28*Assumptions!$B$29 -> 1600000 | H16: =Assumptions!$B$28*Assumptions!$B$29 -> 1600000 | I16: =Assumptions!$B$28*Assumptions!$B$29 -> 1600000 | ... M16: =Assumptions!$B$28*Assumptions!$B$29 -> 1600000
A17: Free-run subsidies | B17: =Assumptions!B21*Assumptions!B22*Assumptions!B17 -> 1593600 | C17: =C5*2*Assumptions!$B$17 -> 50995.2 | D17: =D5*2*Assumptions!$B$17 -> 58899.456 | E17: =E5*2*Assumptions!$B$17 -> 65064.776 | F17: =F5*2*Assumptions!$B$17 -> 69873.725 | G17: =G5*2*Assumptions!$B$17 -> 73624.706 | H17: =H5*2*Assumptions!$B$17 -> 76550.47 | I17: =I5*2*Assumptions!$B$17 -> 78832.567 | J17: =J5*2*Assumptions!$B$17 -> 80612.602 | ... M17: =M5*2*Assumptions!$B$17 -> 83928.722
A18: Other marketing (edit) | B18: 1000000 | C18: 500000 | D18: 0 | E18: 0 | F18: 0 | G18: 0 | H18: 0 | I18: 0 | J18: 0 | K18: 0 | L18: 0 | M18: 0
A19: Fixed opex | B19: =Assumptions!$B$30 -> 500000 | C19: =Assumptions!$B$30 -> 500000 | D19: =Assumptions!$B$30 -> 500000 | E19: =Assumptions!$B$30 -> 500000 | F19: =Assumptions!$B$30 -> 500000 | G19: =Assumptions!$B$30 -> 500000 | H19: =Assumptions!$B$30 -> 500000 | I19: =Assumptions!$B$30 -> 500000 | ... M19: =Assumptions!$B$30 -> 500000
A20: Total costs | B20: =SUM(B16:B19) -> 4693600 | C20: =SUM(C16:C19) -> 2650995.2 | D20: =SUM(D16:D19) -> 2158899.5 | E20: =SUM(E16:E19) -> 2165064.8 | F20: =SUM(F16:F19) -> 2169873.7 | G20: =SUM(G16:G19) -> 2173624.7 | H20: =SUM(H16:H19) -> 2176550.5 | I20: =SUM(I16:I19) -> 2178832.6 | ... M20: =SUM(M16:M19) -> 2183928.7
A21: Net cash flow | B21: =B14-B20 -> -4188272 | C21: =C14-C20 -> -2067341.4 | D21: =D14-D20 -> -1514151.5 | E21: =E14-E20 -> -1472663.3 | F21: =F14-F20 -> -1440302.6 | G21: =G14-G20 -> -1415061.2 | H21: =H14-H20 -> -1395373 | I21: =I14-I20 -> -1380016.1 | ... M21: =M14-M20 -> -1345722.7
A22: Cumulative cash | B22: =B21 -> -4188272 | C22: =B22+C21 -> -6255613.4 | D22: =C22+D21 -> -7769764.8 | E22: =D22+E21 -> -9242428.2 | F22: =E22+F21 -> -10682731 | G22: =F22+G21 -> -12097792 | H22: =G22+H21 -> -13493165 | I22: =H22+I21 -> -14873181 | J22: =I22+J21 -> -16241219 | ... M22: =L22+M21 -> -20297043
A24: Runners needed (utilized) | B24: =B8/(Assumptions!$B$33*Assumptions!$B$35) -> 4.6189376 | C24: =C8/(Assumptions!$B$33*Assumptions!$B$35) -> 5.334873 | D24: =D8/(Assumptions!$B$33*Assumptions!$B$35) -> 5.8933025 | E24: =E8/(Assumptions!$B$33*Assumptions!$B$35) -> 6.3288776 | F24: =F8/(Assumptions!$B$33*Assumptions!$B$35) -> 6.6686261 | G24: =G8/(Assumptions!$B$33*Assumptions!$B$35) -> 6.93363 | H24: =H8/(Assumptions!$B$33*Assumptions!$B$35) -> 7.140333 | I24: =I8/(Assumptions!$B$33*Assumptions!$B$35) -> 7.3015614 | ... M24: =M8/(Assumptions!$B$33*Assumptions!$B$35) -> 7.6616008
A25: Certified runner target | B25: =ROUNDUP(B24*Assumptions!$B$34,0) -> 7 | C25: =ROUNDUP(C24*Assumptions!$B$34,0) -> 9 | D25: =ROUNDUP(D24*Assumptions!$B$34,0) -> 9 | E25: =ROUNDUP(E24*Assumptions!$B$34,0) -> 10 | F25: =ROUNDUP(F24*Assumptions!$B$34,0) -> 11 | G25: =ROUNDUP(G24*Assumptions!$B$34,0) -> 11 | H25: =ROUNDUP(H24*Assumptions!$B$34,0) -> 11 | I25: =ROUNDUP(I24*Assumptions!$B$34,0) -> 11 | ... M25: =ROUNDUP(M24*Assumptions!$B$34,0) -> 12
A27: Month 1 = first paid month (post founding free-run phase). Fractional dogs are fine — it is an expectation model.

Sheet Supply
A1: Runner supply model
A3: Runs per member dog / week | B3: =Assumptions!B9/Assumptions!B35 -> 2.3094688
A4: Dogs served per runner | B4: =Assumptions!B33/B3 -> 3.464
A6: RUNNERS NEEDED BY DEMAND LEVEL
A7: Paying dogs | B7: Runners (utilized) | C7: Certified target (x oversupply)
A8: 25 | B8: =ROUNDUP(A8/$B$4,0) -> 8 | C8: =ROUNDUP(A8/$B$4*Assumptions!$B$34,0) -> 11
A9: 50 | B9: =ROUNDUP(A9/$B$4,0) -> 15 | C9: =ROUNDUP(A9/$B$4*Assumptions!$B$34,0) -> 22
A10: 75 | B10: =ROUNDUP(A10/$B$4,0) -> 22 | C10: =ROUNDUP(A10/$B$4*Assumptions!$B$34,0) -> 33
A11: 100 | B11: =ROUNDUP(A11/$B$4,0) -> 29 | C11: =ROUNDUP(A11/$B$4*Assumptions!$B$34,0) -> 44
A13: Playbook check: Phase 1 target of 20–30 certified runners covers ~45–70 dogs utilized — correct oversupply for a 50-dog Phase-3 goal.
